<?xml version="1.0" ?>
<!-- =================================================================================== -->
<!-- |    This document was autogenerated by xacro from reachback.urdf.xacro           | -->
<!-- |    EDITING THIS FILE BY HAND IS NOT RECOMMENDED                                 | -->
<!-- =================================================================================== -->
<robot name="reachback">
  <material name="clearpath_dark_grey">
    <color rgba="0.2 0.2 0.2 1.0"/>
  </material>
  <material name="clearpath_medium_grey">
    <color rgba="0.6 0.6 0.6 1.0"/>
  </material>
  <material name="clearpath_light_grey">
    <color rgba="0.8 0.8 0.8 1.0"/>
  </material>
  <material name="clearpath_yellow">
    <color rgba="0.8 0.8 0.0 1.0"/>
  </material>
  <material name="clearpath_black">
    <color rgba="0.15 0.15 0.15 1.0"/>
  </material>
  <material name="clearpath_white">
    <color rgba="1.0 1.0 1.0 1.0"/>
  </material>
  <material name="clearpath_red">
    <color rgba="1.0 0.0 0.0 1.0"/>
  </material>
  <material name="clearpath_aluminum">
    <color rgba="0.5 0.5 0.5 1"/>
  </material>
  <material name="clearpath_plastic">
    <color rgba="0.1 0.1 0.1   1"/>
  </material>

  <link name="base_footprint" />
  <joint name="base_joint" type="planar">
    <parent link="base_footprint"/>
    <child link="base_link"/>
    <origin xyz="0 0 0" rpy="0 0 0"/>
    <axis xyz="0 0 1"/>
  </joint>
  <!-- Chassis -->
  <link name="base_link"/>
  <joint name="base_link_joint" type="fixed">
    <origin rpy="0 0 0" xyz="0 0 0"/>
    <parent link="base_link"/>
    <child link="chassis_link"/>
  </joint>
  <link name="chassis_link">
    <visual>
      <origin rpy="0 0 0" xyz="0 0 0"/>
      <geometry>
        <mesh filename="package://roboplan_example_models/models/reachback_robot_model/meshes/r100/body.stl"/>
      </geometry>
      <material name="clearpath_black"/>
    </visual>
    <collision>
      <origin xyz="0 0 0"/>
      <geometry>
        <mesh filename="package://roboplan_example_models/models/reachback_robot_model/meshes/r100/body-collision.stl"/>
      </geometry>
    </collision>
    <inertial>
      <origin rpy="1.5707963267948966 0 1.5707963267948966" xyz="0.012 0.002 0.067"/>
      <mass value="165.304"/>
      <inertia ixx="4.4744" ixy="0.03098" ixz="0.003647" iyy="7.1624" iyz="0.1228" izz="4.6155"/>
    </inertial>
  </link>
  <!-- Covers -->
  <joint name="right_side_cover_link_joint" type="fixed">
    <origin rpy="0 0 0" xyz="0 0 0"/>
    <parent link="chassis_link"/>
    <child link="right_side_cover_link"/>
  </joint>
  <joint name="left_side_cover_link_joint" type="fixed">
    <origin rpy="0 0 0" xyz="0 0 0"/>
    <parent link="chassis_link"/>
    <child link="left_side_cover_link"/>
  </joint>
  <link name="left_side_cover_link">
    <visual>
      <origin rpy="0 0 3.141592653589793" xyz="0 0 0"/>
      <geometry>
        <mesh filename="package://roboplan_example_models/models/reachback_robot_model/meshes/r100/side-cover.stl"/>
      </geometry>
      <material name="clearpath_yellow"/>
    </visual>
    <collision>
      <origin rpy="0 0 3.141592653589793" xyz="0 0 0"/>
      <geometry>
        <mesh filename="package://roboplan_example_models/models/reachback_robot_model/meshes/r100/side-cover.stl"/>
      </geometry>
    </collision>
  </link>
  <link name="right_side_cover_link">
    <visual>
      <origin rpy="0 0 0" xyz="0 0 0"/>
      <geometry>
        <mesh filename="package://roboplan_example_models/models/reachback_robot_model/meshes/r100/side-cover.stl"/>
      </geometry>
      <material name="clearpath_yellow"/>
    </visual>
    <collision>
      <origin rpy="0 0 0" xyz="0 0 0"/>
      <geometry>
        <mesh filename="package://roboplan_example_models/models/reachback_robot_model/meshes/r100/side-cover.stl"/>
      </geometry>
    </collision>
  </link>
  <joint name="front_cover_link_joint" type="fixed">
    <origin rpy="0 0 0" xyz="0 0 0"/>
    <parent link="chassis_link"/>
    <child link="front_cover_link"/>
  </joint>
  <link name="front_cover_link">
    <visual>
      <origin rpy="0 0 0" xyz="0 0 0"/>
      <geometry>
        <mesh filename="package://roboplan_example_models/models/reachback_robot_model/meshes/r100/end-cover.stl"/>
      </geometry>
      <material name="clearpath_black"/>
    </visual>
    <collision>
      <origin rpy="0 0 0" xyz="0 0 0"/>
      <geometry>
        <mesh filename="package://roboplan_example_models/models/reachback_robot_model/meshes/r100/end-cover.stl"/>
      </geometry>
    </collision>
  </link>
  <joint name="rear_cover_link_joint" type="fixed">
    <origin rpy="0 0 0" xyz="0 0 0"/>
    <parent link="chassis_link"/>
    <child link="rear_cover_link"/>
  </joint>
  <link name="rear_cover_link">
    <visual>
      <origin rpy="0 0 3.141592653589793" xyz="0 0 0"/>
      <geometry>
        <mesh filename="package://roboplan_example_models/models/reachback_robot_model/meshes/r100/end-cover.stl"/>
      </geometry>
      <material name="clearpath_black"/>
    </visual>
    <collision>
      <origin rpy="0 0 3.141592653589793" xyz="0 0 0"/>
      <geometry>
        <mesh filename="package://roboplan_example_models/models/reachback_robot_model/meshes/r100/end-cover.stl"/>
      </geometry>
    </collision>
  </link>
  <!-- Lights -->
  <joint name="front_lights_link_joint" type="fixed">
    <origin rpy="0 0 0" xyz="0 0 0"/>
    <parent link="chassis_link"/>
    <child link="front_lights_link"/>
  </joint>
  <joint name="rear_lights_link_joint" type="fixed">
    <origin rpy="0 0 0" xyz="0 0 0"/>
    <parent link="chassis_link"/>
    <child link="rear_lights_link"/>
  </joint>
  <link name="front_lights_link">
    <visual>
      <origin rpy="0 0 0" xyz="0 0 0"/>
      <geometry>
        <mesh filename="package://roboplan_example_models/models/reachback_robot_model/meshes/r100/lights.stl"/>
      </geometry>
      <material name="clearpath_white"/>
    </visual>
    <collision>
      <origin rpy="0 0 0" xyz="0 0 0"/>
      <geometry>
        <mesh filename="package://roboplan_example_models/models/reachback_robot_model/meshes/r100/lights.stl"/>
      </geometry>
    </collision>
  </link>
  <link name="rear_lights_link">
    <visual>
      <origin rpy="0 0 3.141592653589793" xyz="0 0 0"/>
      <geometry>
        <mesh filename="package://roboplan_example_models/models/reachback_robot_model/meshes/r100/lights.stl"/>
      </geometry>
      <material name="clearpath_red"/>
    </visual>
    <collision>
      <origin rpy="0 0 3.141592653589793" xyz="0 0 0"/>
      <geometry>
        <mesh filename="package://roboplan_example_models/models/reachback_robot_model/meshes/r100/lights.stl"/>
      </geometry>
    </collision>
  </link>
  <!-- Axle -->
  <joint name="axle_joint" type="fixed">
    <origin rpy="0 0 0" xyz="0 0 0.05"/>
    <parent link="chassis_link"/>
    <child link="axle_link"/>
  </joint>
  <link name="axle_link">
    <visual>
      <origin rpy="0 1.5707963267948966 0" xyz="0 0 0"/>
      <geometry>
        <mesh filename="package://roboplan_example_models/models/reachback_robot_model/meshes/r100/axle.stl"/>
      </geometry>
      <material name="clearpath_black"/>
    </visual>
    <collision>
      <origin rpy="0 1.5707963267948966 0" xyz="0 0 0"/>
      <geometry>
        <mesh filename="package://roboplan_example_models/models/reachback_robot_model/meshes/r100/axle.stl"/>
      </geometry>
    </collision>
  </link>
  <!-- Riser -->
  <joint name="riser_link_joint" type="fixed">
    <origin rpy="0 0 0" xyz="0 0 0.22"/>
    <parent link="chassis_link"/>
    <child link="riser_link"/>
  </joint>
  <link name="riser_link">
    <visual>
      <origin rpy="0 0 0.7853981633974483" xyz="0 0 0.035"/>
      <geometry>
        <box size="0.493 0.493 0.07"/>
      </geometry>
      <material name="clearpath_light_grey"/>
    </visual>
    <collision>
      <origin rpy="0 0 0.7853981633974483" xyz="0 0 0.035"/>
      <geometry>
        <box size="0.493 0.493 0.07"/>
      </geometry>
    </collision>
  </link>
  <!-- Top Plate -->
  <joint name="top_link_joint" type="fixed">
    <origin rpy="0 0 0" xyz="0 0 -0.20500000000000002"/>
    <parent link="riser_link"/>
    <child link="top_link"/>
  </joint>
  <link name="top_link">
    <visual>
      <origin rpy="0 0 0" xyz="0 0 0"/>
      <geometry>
        <mesh filename="package://roboplan_example_models/models/reachback_robot_model/meshes/r100/top.stl"/>
      </geometry>
      <material name="clearpath_black"/>
    </visual>
    <collision>
      <origin rpy="0 0 0" xyz="0 0 0"/>
      <geometry>
        <mesh filename="package://roboplan_example_models/models/reachback_robot_model/meshes/r100/top.stl"/>
      </geometry>
    </collision>
  </link>
  <!-- Front Wheels -->
  <link name="front_rocker_link">
    <visual>
      <origin rpy="1.5707963267948966 0 1.5707963267948966" xyz="0 0 0"/>
      <geometry>
        <mesh filename="package://roboplan_example_models/models/reachback_robot_model/meshes/r100/rocker.stl"/>
      </geometry>
      <material name="clearpath_black"/>
    </visual>
    <collision>
      <origin rpy="1.5707963267948966 0 1.5707963267948966" xyz="0 0 0"/>
      <geometry>
        <mesh filename="package://roboplan_example_models/models/reachback_robot_model/meshes/r100/rocker.stl"/>
      </geometry>
      <material name="clearpath_black"/>
    </collision>
    <inertial>
      <origin rpy="1.5707963267948966 0 1.5707963267948966" xyz="0 0 0"/>
      <mass value="10.267"/>
      <inertia ixx="0.0288" ixy="2.20484e-6" ixz="-1.3145e-5" iyy="0.4324" iyz="1.8944e-3" izz="0.4130"/>
    </inertial>
  </link>
  <joint name="front_rocker" type="fixed">
    <parent link="axle_link"/>
    <child link="front_rocker_link"/>
    <origin rpy="0 0 0" xyz="0.319 0 0"/>
    <axis xyz="1 0 0"/>
    <limit effort="0" lower="-0.08726" upper="0.08726" velocity="0"/>
  </joint>
  <link name="front_left_wheel_link">
    <visual>
      <origin rpy="1.5707963267948966 0 0" xyz="0 0 0"/>
      <geometry>
        <mesh filename="package://roboplan_example_models/models/reachback_robot_model/meshes/r100/wheels/mecanum.stl"/>
      </geometry>
      <material name="clearpath_black"/>
    </visual>
    <collision>
      <origin rpy="1.5707963267948966 0 0" xyz="0 0 0"/>
      <geometry>
        <cylinder length="0.079" radius="0.0759"/>
      </geometry>
    </collision>
    <inertial>
      <origin rpy="0 0 0" xyz="0 0 0"/>
      <mass value="2.5"/>
      <inertia ixx="0.0049007145833333335" ixy="0" ixz="0" iyy="0.0072010124999999986" iyz="0" izz="0.0049007145833333335"/>
    </inertial>
  </link>
  <joint name="front_left_wheel_joint" type="continuous">
    <parent link="front_rocker_link"/>
    <child link="front_left_wheel_link"/>
    <origin rpy="0 0 0" xyz="0 0.27549999999999997 0"/>
    <axis xyz="0 1 0"/>
  </joint>
  <link name="front_right_wheel_link">
    <visual>
      <origin rpy="1.5707963267948966 0 0" xyz="0 0 0"/>
      <geometry>
        <mesh filename="package://roboplan_example_models/models/reachback_robot_model/meshes/r100/wheels/mecanum.stl"/>
      </geometry>
      <material name="clearpath_black"/>
    </visual>
    <collision>
      <origin rpy="1.5707963267948966 0 0" xyz="0 0 0"/>
      <geometry>
        <cylinder length="0.079" radius="0.0759"/>
      </geometry>
    </collision>
    <inertial>
      <origin rpy="0 0 0" xyz="0 0 0"/>
      <mass value="2.5"/>
      <inertia ixx="0.0049007145833333335" ixy="0" ixz="0" iyy="0.0072010124999999986" iyz="0" izz="0.0049007145833333335"/>
    </inertial>
  </link>
  <joint name="front_right_wheel_joint" type="continuous">
    <parent link="front_rocker_link"/>
    <child link="front_right_wheel_link"/>
    <origin rpy="0 0 0" xyz="0 -0.27549999999999997 0"/>
    <axis xyz="0 1 0"/>
  </joint>
  <!-- Rear Wheels -->
  <link name="rear_rocker_link">
    <visual>
      <origin rpy="1.5707963267948966 0 1.5707963267948966" xyz="0 0 0"/>
      <geometry>
        <mesh filename="package://roboplan_example_models/models/reachback_robot_model/meshes/r100/rocker.stl"/>
      </geometry>
      <material name="clearpath_black"/>
    </visual>
    <collision>
      <origin rpy="1.5707963267948966 0 1.5707963267948966" xyz="0 0 0"/>
      <geometry>
        <mesh filename="package://roboplan_example_models/models/reachback_robot_model/meshes/r100/rocker.stl"/>
      </geometry>
      <material name="clearpath_black"/>
    </collision>
    <inertial>
      <origin rpy="1.5707963267948966 0 1.5707963267948966" xyz="0 0 0"/>
      <mass value="10.267"/>
      <inertia ixx="0.0288" ixy="2.20484e-6" ixz="-1.3145e-5" iyy="0.4324" iyz="1.8944e-3" izz="0.4130"/>
    </inertial>
  </link>
  <joint name="rear_rocker" type="fixed">
    <parent link="axle_link"/>
    <child link="rear_rocker_link"/>
    <origin rpy="0 0 0" xyz="-0.319 0 0"/>
    <axis xyz="1 0 0"/>
    <limit effort="0" velocity="0"/>
  </joint>
  <link name="rear_left_wheel_link">
    <visual>
      <origin rpy="1.5707963267948966 0 0" xyz="0 0 0"/>
      <geometry>
        <mesh filename="package://roboplan_example_models/models/reachback_robot_model/meshes/r100/wheels/mecanum.stl"/>
      </geometry>
      <material name="clearpath_black"/>
    </visual>
    <collision>
      <origin rpy="1.5707963267948966 0 0" xyz="0 0 0"/>
      <geometry>
        <cylinder length="0.079" radius="0.0759"/>
      </geometry>
    </collision>
    <inertial>
      <origin rpy="0 0 0" xyz="0 0 0"/>
      <mass value="2.5"/>
      <inertia ixx="0.0049007145833333335" ixy="0" ixz="0" iyy="0.0072010124999999986" iyz="0" izz="0.0049007145833333335"/>
    </inertial>
  </link>
  <joint name="rear_left_wheel_joint" type="continuous">
    <parent link="rear_rocker_link"/>
    <child link="rear_left_wheel_link"/>
    <origin rpy="0 0 0" xyz="0 0.27549999999999997 0"/>
    <axis xyz="0 1 0"/>
  </joint>
  <link name="rear_right_wheel_link">
    <visual>
      <origin rpy="1.5707963267948966 0 0" xyz="0 0 0"/>
      <geometry>
        <mesh filename="package://roboplan_example_models/models/reachback_robot_model/meshes/r100/wheels/mecanum.stl"/>
      </geometry>
      <material name="clearpath_black"/>
    </visual>
    <collision>
      <origin rpy="1.5707963267948966 0 0" xyz="0 0 0"/>
      <geometry>
        <cylinder length="0.079" radius="0.0759"/>
      </geometry>
    </collision>
    <inertial>
      <origin rpy="0 0 0" xyz="0 0 0"/>
      <mass value="2.5"/>
      <inertia ixx="0.0049007145833333335" ixy="0" ixz="0" iyy="0.0072010124999999986" iyz="0" izz="0.0049007145833333335"/>
    </inertial>
  </link>
  <joint name="rear_right_wheel_joint" type="continuous">
    <parent link="rear_rocker_link"/>
    <child link="rear_right_wheel_link"/>
    <origin rpy="0 0 0" xyz="0 -0.27549999999999997 0"/>
    <axis xyz="0 1 0"/>
  </joint>
  <!-- ROS2 controls -->
  <ros2_control name="r100_hardware" type="system">
    <hardware>
      <plugin>mock_components/GenericSystem</plugin>
    </hardware>
    <joint name="front_left_wheel_joint">
      <command_interface name="velocity"/>
      <state_interface name="position"/>
      <state_interface name="velocity"/>
    </joint>
    <joint name="front_right_wheel_joint">
      <command_interface name="velocity"/>
      <state_interface name="position"/>
      <state_interface name="velocity"/>
    </joint>
    <joint name="rear_left_wheel_joint">
      <command_interface name="velocity"/>
      <state_interface name="position"/>
      <state_interface name="velocity"/>
    </joint>
    <joint name="rear_right_wheel_joint">
      <command_interface name="velocity"/>
      <state_interface name="position"/>
      <state_interface name="velocity"/>
    </joint>
  </ros2_control>
  <!-- Internal IMU -->
  <link name="imu_0_link">
    <inertial>
      <mass value="0.001"/>
      <origin rpy="0 0 0" xyz="0 0 0"/>
      <inertia ixx="1e-09" ixy="0.0" ixz="0.0" iyy="1e-09" iyz="0.0" izz="1e-09"/>
    </inertial>
  </link>
  <joint name="imu_0_joint" type="fixed">
    <parent link="chassis_link"/>
    <child link="imu_0_link"/>
    <origin rpy="0 0 0" xyz="0.2085 -0.2902 0.1681"/>
  </joint>
  <!-- Mounting Hardpoints -->
  <link name="default_mount"/>
  <joint name="default_mount_joint" type="fixed">
    <parent link="riser_link"/>
    <child link="default_mount"/>
    <origin rpy="0 0 0" xyz="0 0 0.07500000000000001"/>
  </joint>
  <link name="laser_0_link">
    <visual>
      <origin rpy="0 0 0" xyz="0 0 0"/>
      <geometry>
        <!-- Origin of this mesh is the base of the bracket. -->
        <mesh filename="package://roboplan_example_models/models/reachback_robot_model/meshes/hokuyo_ust.stl"/>
      </geometry>
      <material name="clearpath_dark_grey"/>
    </visual>
    <collision>
      <origin rpy="0 0 0" xyz="0 0 0"/>
      <geometry>
        <mesh filename="package://roboplan_example_models/models/reachback_robot_model/meshes/hokuyo_ust.stl"/>
      </geometry>
      <material name="clearpath_dark_grey"/>
    </collision>
  </link>
  <link name="laser_0_laser">
    <inertial>
      <mass value="1.1"/>
      <origin xyz="0 0 0"/>
      <inertia ixx="0.00307156543804" ixy="0.0" ixz="0.0" iyy="0.0031284904152700005" iyz="0.0" izz="0.00196432421427"/>
    </inertial>
  </link>
  <joint name="laser_0_joint" type="fixed">
    <origin rpy="0.0 0.0 0.0" xyz="0.3922 0.0 0.1856"/>
    <parent link="chassis_link"/>
    <child link="laser_0_link"/>
  </joint>
  <joint name="laser_0_laser_joint" type="fixed">
    <!-- This offset is from the base of the bracket to the LIDAR's focal point. -->
    <origin rpy="0 0 0" xyz="0 0 0.0474"/>
    <parent link="laser_0_link"/>
    <child link="laser_0_laser"/>
  </joint>
  <link name="laser_1_link">
    <visual>
      <origin rpy="0 0 0" xyz="0 0 0"/>
      <geometry>
        <!-- Origin of this mesh is the base of the bracket. -->
        <mesh filename="package://roboplan_example_models/models/reachback_robot_model/meshes/hokuyo_ust.stl"/>
      </geometry>
      <material name="clearpath_dark_grey"/>
    </visual>
    <collision>
      <origin rpy="0 0 0" xyz="0 0 0"/>
      <geometry>
        <mesh filename="package://roboplan_example_models/models/reachback_robot_model/meshes/hokuyo_ust.stl"/>
      </geometry>
      <material name="clearpath_dark_grey"/>
    </collision>
  </link>
  <link name="laser_1_laser">
    <inertial>
      <mass value="1.1"/>
      <origin xyz="0 0 0"/>
      <inertia ixx="0.00307156543804" ixy="0.0" ixz="0.0" iyy="0.0031284904152700005" iyz="0.0" izz="0.00196432421427"/>
    </inertial>
  </link>
  <joint name="laser_1_joint" type="fixed">
    <origin rpy="0.0 0.0 3.14159" xyz="-0.3922 0.0 0.1856"/>
    <parent link="chassis_link"/>
    <child link="laser_1_link"/>
  </joint>
  <joint name="laser_1_laser_joint" type="fixed">
    <!-- This offset is from the base of the bracket to the LIDAR's focal point. -->
    <origin rpy="0 0 0" xyz="0 0 0.0474"/>
    <parent link="laser_1_link"/>
    <child link="laser_1_laser"/>
  </joint>
  <material name="black">
    <color rgba="0.0 0.0 0.0 1.0"/>
  </material>
  <material name="white">
    <color rgba="1.0 1.0 1.0 1.0"/>
  </material>
  <material name="orange">
    <color rgba="1.0 0.4 0.0 1.0"/>
  </material>
  <material name="dr_gray">
    <color rgba="0.490 0.490 0.486 1.0"/>
  </material>
  <material name="dr_white">
    <color rgba="0.941 0.941 0.941 1.0"/>
  </material>
  <material name="dr_blue">
    <color rgba="0 0 0.15 1"/>
  </material>
  <material name="grey">
    <color rgba="0.5 0.5 0.5 1.0"/>
  </material>
  <material name="Boxer_DarkGrey">
    <color rgba="0.3 0.3 0.3 1.0"/>
  </material>
  <link name="arm_base_link">
    <inertial>
      <mass value="8.537"/>
      <origin xyz="1.8e-05   -0.002377    0.095608"/>
      <inertia ixx="0.079499" ixy="2.9382e-05" ixz="1.7529e-05" iyy="0.076993" iyz="-0.0009938" izz="0.067833"/>
    </inertial>
    <collision>
      <origin rpy="0 0 0" xyz="0 0 0"/>
      <geometry>
        <mesh filename="package://roboplan_example_models/models/reachback_robot_model/meshes/h2017/H2017_0_0.stl"/>
      </geometry>
    </collision>
    <visual>
      <origin rpy="0 0 0" xyz="0 0 0"/>
      <geometry>
        <mesh filename="package://roboplan_example_models/models/reachback_robot_model/meshes/h2017/H2017_0_0.stl"/>
      </geometry>
    </visual>
  </link>
  <!-- joint 1 -->
  <joint name="arm_joint_1" type="revolute">
    <parent link="arm_base_link"/>
    <child link="arm_link_1"/>
    <origin rpy="0 0 0" xyz="0 0 0.3443"/>
    <axis xyz="0 0 1"/>
    <limit effort="372" lower="-6.2832" upper="6.2832" velocity="1.7453"/>
    <dynamics friction="0"/>
  </joint>
  <link name="arm_link_1">
    <inertial>
      <mass value="20.253"/>
      <origin xyz="-5e-05     0.11854   -0.059979"/>
      <inertia ixx="0.5323" ixy="-6.2817e-05" ixz="-7.5664e-06" iyy="0.2807" iyz="-0.14899" izz="0.34857"/>
    </inertial>
    <collision>
      <origin rpy="0 0 0" xyz="0 0 0"/>
      <geometry>
        <mesh filename="package://roboplan_example_models/models/reachback_robot_model/meshes/h2017/H2017_1_0.stl"/>
      </geometry>
    </collision>
    <visual>
      <origin rpy="0 0 0" xyz="0 0 0"/>
      <geometry>
        <mesh filename="package://roboplan_example_models/models/reachback_robot_model/meshes/h2017/H2017_1_0.stl"/>
      </geometry>
    </visual>
  </link>
  <!-- joint2 -->
  <joint name="arm_joint_2" type="revolute">
    <parent link="arm_link_1"/>
    <child link="arm_link_2"/>
    <origin rpy="0 -1.571 -1.571" xyz="0 0.0099 0"/>
    <axis xyz="0 0 1"/>
    <limit effort="372" lower="-2.1817" upper="2.1817" velocity="1.3963"/>
    <dynamics friction="0"/>
  </joint>
  <link name="arm_link_2">
    <inertial>
      <mass value="28.536"/>
      <origin xyz="0.38055    -1.7e-05     0.22527"/>
      <inertia ixx="0.15388" ixy="-0.00022213" ixz="0.11801" iyy="3.0424" iyz="-5.3325e-05" izz="3.0015"/>
    </inertial>
    <collision>
      <origin rpy="0 0 0" xyz="0 0 0"/>
      <geometry>
        <mesh filename="package://roboplan_example_models/models/reachback_robot_model/meshes/h2017/H2017_2_0.stl"/>
      </geometry>
    </collision>
    <visual>
      <origin rpy="0 0 0" xyz="0 0 0"/>
      <geometry>
        <mesh filename="package://roboplan_example_models/models/reachback_robot_model/meshes/h2017/H2017_2_0.stl"/>
      </geometry>
    </visual>
    <collision>
      <origin rpy="0 0 0" xyz="0 0 0"/>
      <geometry>
        <mesh filename="package://roboplan_example_models/models/reachback_robot_model/meshes/h2017/H2017_2_1.stl"/>
      </geometry>
    </collision>
    <visual>
      <origin rpy="0 0 0" xyz="0 0 0"/>
      <geometry>
        <mesh filename="package://roboplan_example_models/models/reachback_robot_model/meshes/h2017/H2017_2_1.stl"/>
      </geometry>
    </visual>
    <collision>
      <origin rpy="0 0 0" xyz="0 0 0"/>
      <geometry>
        <mesh filename="package://roboplan_example_models/models/reachback_robot_model/meshes/h2017/H2017_2_2.stl"/>
      </geometry>
    </collision>
    <visual>
      <origin rpy="0 0 0" xyz="0 0 0"/>
      <geometry>
        <mesh filename="package://roboplan_example_models/models/reachback_robot_model/meshes/h2017/H2017_2_2.stl"/>
      </geometry>
    </visual>
  </link>
  <!-- joint3 -->
  <joint name="arm_joint_3" type="revolute">
    <parent link="arm_link_2"/>
    <child link="arm_link_3"/>
    <origin rpy="0 0 1.571" xyz="0.845 0 0"/>
    <axis xyz="0 0 1"/>
    <limit effort="372" lower="-2.7925" upper="2.7925" velocity="1.7453"/>
    <dynamics friction="0"/>
  </joint>
  <link name="arm_link_3">
    <inertial>
      <mass value="6.421"/>
      <origin xyz="-5.9e-05   -0.008325    0.049527"/>
      <inertia ixx="0.04463" ixy="3.0207e-05" ixz="-1.0987e-05" iyy="0.041031" iyz="-0.0029929" izz="0.028983"/>
    </inertial>
    <collision>
      <origin rpy="0 0 0" xyz="0 0 0"/>
      <geometry>
        <mesh filename="package://roboplan_example_models/models/reachback_robot_model/meshes/h2017/H2017_3_0.stl"/>
      </geometry>
    </collision>
    <visual>
      <origin rpy="0 0 0" xyz="0 0 0"/>
      <geometry>
        <mesh filename="package://roboplan_example_models/models/reachback_robot_model/meshes/h2017/H2017_3_0.stl"/>
      </geometry>
    </visual>
  </link>
  <!-- joint4 -->
  <joint name="arm_joint_4" type="revolute">
    <parent link="arm_link_3"/>
    <child link="arm_link_4"/>
    <origin rpy="1.571 0 0" xyz="0 -0.734 0"/>
    <axis xyz="0 0 1"/>
    <limit effort="163" lower="-6.2832" upper="6.2832" velocity="3.1416"/>
    <dynamics friction="0"/>
  </joint>
  <link name="arm_link_4">
    <inertial>
      <mass value="7.59"/>
      <origin xyz="7.7e-05     0.12896    -0.22056"/>
      <inertia ixx="0.60329" ixy="-6.8213e-05" ixz="-0.00013439" iyy="0.54966" iyz="-0.159" izz="0.078126"/>
    </inertial>
    <collision>
      <origin rpy="0 0 0" xyz="0 0 0"/>
      <geometry>
        <mesh filename="package://roboplan_example_models/models/reachback_robot_model/meshes/h2017/H2017_4_0.stl"/>
      </geometry>
    </collision>
    <visual>
      <origin rpy="0 0 0" xyz="0 0 0"/>
      <geometry>
        <mesh filename="package://roboplan_example_models/models/reachback_robot_model/meshes/h2017/H2017_4_0.stl"/>
      </geometry>
    </visual>
    <collision>
      <origin rpy="0 0 0" xyz="0 0 0"/>
      <geometry>
        <mesh filename="package://roboplan_example_models/models/reachback_robot_model/meshes/h2017/H2017_4_1.stl"/>
      </geometry>
    </collision>
    <visual>
      <origin rpy="0 0 0" xyz="0 0 0"/>
      <geometry>
        <mesh filename="package://roboplan_example_models/models/reachback_robot_model/meshes/h2017/H2017_4_1.stl"/>
      </geometry>
    </visual>
  </link>
  <!-- joint5 -->
  <joint name="arm_joint_5" type="revolute">
    <parent link="arm_link_4"/>
    <child link="arm_link_5"/>
    <origin rpy="-1.571 0 0" xyz="0 0 0"/>
    <axis xyz="0 0 1"/>
    <limit effort="96" lower="-6.2832" upper="6.2832" velocity="3.1416"/>
    <dynamics friction="0"/>
  </joint>
  <link name="arm_link_5">
    <inertial>
      <mass value="4.099"/>
      <origin xyz="-6.1e-05   -0.000589    0.048812"/>
      <inertia ixx="0.021303" ixy="2.545e-05" ixz="-4.3439e-06" iyy="0.023894" iyz="6.0426e-05" izz="0.014587"/>
    </inertial>
    <collision>
      <origin rpy="0 0 0" xyz="0 0 0"/>
      <geometry>
        <mesh filename="package://roboplan_example_models/models/reachback_robot_model/meshes/h2017/H2017_5_0.stl"/>
      </geometry>
    </collision>
    <visual>
      <origin rpy="0 0 0" xyz="0 0 0"/>
      <geometry>
        <mesh filename="package://roboplan_example_models/models/reachback_robot_model/meshes/h2017/H2017_5_0.stl"/>
      </geometry>
    </visual>
  </link>
  <!-- joint6 -->
  <joint name="arm_joint_6" type="revolute">
    <parent link="arm_link_5"/>
    <child link="arm_link_6"/>
    <origin rpy="1.571 0 0" xyz="0 -0.121 0"/>
    <axis xyz="0 0 1"/>
    <limit effort="50" lower="-6.2832" upper="6.2832" velocity="3.927"/>
    <dynamics friction="0"/>
  </joint>
  <link name="arm_link_6">
    <inertial>
      <mass value="0.897"/>
      <origin xyz="-3.3e-05     3.6e-05   -0.049443"/>
      <inertia ixx="0.0086582" ixy="7.8198e-06" ixz="2.2495e-06" iyy="0.0068184" iyz="5.6115e-06" izz="0.0080729"/>
    </inertial>
    <collision>
      <origin rpy="0 0 0" xyz="0 0 0"/>
      <geometry>
        <mesh filename="package://roboplan_example_models/models/reachback_robot_model/meshes/h2017/H2017_6_0.stl"/>
      </geometry>
    </collision>
    <visual>
      <origin rpy="0 0 0" xyz="0 0 0"/>
      <geometry>
        <mesh filename="package://roboplan_example_models/models/reachback_robot_model/meshes/h2017/H2017_6_0.stl"/>
      </geometry>
    </visual>
  </link>
  <!-- Transmission 1 -->
  <transmission name="tran1">
    <type>transmission_interface/SimpleTransmission</type>
    <joint name="joint1">
      <hardwareInterface>hardware_interface/PositionJointInterface</hardwareInterface>
    </joint>
    <actuator name="motor1">
      <mechanicalReduction>1</mechanicalReduction>
    </actuator>
  </transmission>
  <!-- Transmission 2 -->
  <transmission name="tran2">
    <type>transmission_interface/SimpleTransmission</type>
    <joint name="joint2">
      <hardwareInterface>hardware_interface/PositionJointInterface</hardwareInterface>
    </joint>
    <actuator name="motor2">
      <mechanicalReduction>1</mechanicalReduction>
    </actuator>
  </transmission>
  <!-- Transmission 3 -->
  <transmission name="tran3">
    <type>transmission_interface/SimpleTransmission</type>
    <joint name="joint3">
      <hardwareInterface>hardware_interface/PositionJointInterface</hardwareInterface>
    </joint>
    <actuator name="motor3">
      <mechanicalReduction>1</mechanicalReduction>
    </actuator>
  </transmission>
  <!-- Transmission 4 -->
  <transmission name="tran4">
    <type>transmission_interface/SimpleTransmission</type>
    <joint name="joint4">
      <hardwareInterface>hardware_interface/PositionJointInterface</hardwareInterface>
    </joint>
    <actuator name="motor4">
      <mechanicalReduction>1</mechanicalReduction>
    </actuator>
  </transmission>
  <!-- Transmission 5 -->
  <transmission name="tran5">
    <type>transmission_interface/SimpleTransmission</type>
    <joint name="joint5">
      <hardwareInterface>hardware_interface/PositionJointInterface</hardwareInterface>
    </joint>
    <actuator name="motor5">
      <mechanicalReduction>1</mechanicalReduction>
    </actuator>
  </transmission>
  <!-- Transmission 6 -->
  <transmission name="tran6">
    <type>transmission_interface/SimpleTransmission</type>
    <joint name="joint6">
      <hardwareInterface>hardware_interface/PositionJointInterface</hardwareInterface>
    </joint>
    <actuator name="motor6">
      <mechanicalReduction>1</mechanicalReduction>
    </actuator>
  </transmission>
  <!-- ros_control plugin -->
  <!-- Base -->
  <!-- Link1 -->
  <!-- Link2 -->
  <!-- Link3 -->
  <!-- Link4 -->
  <!-- Link5 -->
  <!-- Link6 -->
  <link name="arm_tool0"/>
  <joint name="arm_joint_6-arm_tool0" type="fixed">
    <origin rpy="3.1415926535 -1.570796327 0" xyz="0 0 0"/>
    <parent link="arm_link_6"/>
    <child link="arm_tool0"/>
  </joint>
  <link name="arm_eoat_adapter">
    <collision>
      <origin rpy="0 0 0" xyz="0 0 0"/>
      <geometry>
        <mesh filename="package://roboplan_example_models/models/reachback_robot_model/meshes/eoat-adapter.stl"/>
      </geometry>
    </collision>
    <visual>
      <origin rpy="0 0 0" xyz="0 0 0"/>
      <geometry>
        <mesh filename="package://roboplan_example_models/models/reachback_robot_model/meshes/eoat-adapter.stl"/>
      </geometry>
      <material name="grey">
        <color rgba="0.5 0.5 0.5 1.0"/>
      </material>
    </visual>
  </link>
  <joint name="arm_tool0-arm_eoat_adapter" type="fixed">
    <origin rpy="-0.78 0 1.57" xyz="0.03 0.0 0.03"/>
    <parent link="arm_tool0"/>
    <child link="arm_eoat_adapter"/>
  </joint>
  <link name="arm_gripper">
    <collision>
      <origin rpy="0 0 0" xyz="0 0 0"/>
      <geometry>
        <mesh filename="package://roboplan_example_models/models/reachback_robot_model/meshes/gripper.stl"/>
      </geometry>
    </collision>
    <visual>
      <origin rpy="0 0 0" xyz="0 0 0"/>
      <geometry>
        <mesh filename="package://roboplan_example_models/models/reachback_robot_model/meshes/gripper.stl"/>
      </geometry>
      <material name="grey">
        <color rgba="0.5 0.5 0.5 1.0"/>
      </material>
    </visual>
  </link>
  <joint name="arm_eoat_adapter-arm_gripper" type="fixed">
    <origin rpy="0 0 0" xyz="0 0 0"/>
    <parent link="arm_eoat_adapter"/>
    <child link="arm_gripper"/>
  </joint>
  <link name="arm_finger_b">
    <visual>
      <origin rpy="0 0 0" xyz="0 0 0"/>
      <geometry>
        <mesh filename="package://roboplan_example_models/models/reachback_robot_model/meshes/finger-b.stl"/>
      </geometry>
      <material name="white">
        <color rgba="1 1 1 1.0"/>
      </material>
    </visual>
    <collision>
      <origin rpy="0 0 0" xyz="0 0 0"/>
      <geometry>
        <mesh filename="package://roboplan_example_models/models/reachback_robot_model/meshes/finger-b.stl"/>
      </geometry>
    </collision>
  </link>
  <link name="arm_finger_a">
    <visual>
      <geometry>
        <mesh filename="package://roboplan_example_models/models/reachback_robot_model/meshes/finger-a.stl"/>
      </geometry>
      <material name="white">
        <color rgba="1 1 1 1.0"/>
      </material>
    </visual>
    <collision>
      <geometry>
        <mesh filename="package://roboplan_example_models/models/reachback_robot_model/meshes/finger-a.stl"/>
      </geometry>
    </collision>
  </link>
  <joint name="arm_finger_a_joint" type="prismatic">
    <parent link="arm_gripper"/>
    <child link="arm_finger_a"/>
    <origin rpy="0 0 0" xyz="0 0 0"/>
    <axis xyz="0 0 -1"/>
    <limit effort="20" lower="-0.005" upper="0.055" velocity="0.225"/>
  </joint>
  <joint name="arm_finger_b_joint" type="prismatic">
    <parent link="arm_gripper"/>
    <child link="arm_finger_b"/>
    <origin rpy="0 0 0" xyz="0 0 0"/>
    <axis xyz="0 0 1"/>
    <limit effort="20" lower="-0.005" upper="0.055" velocity="0.225"/>
    <mimic joint="arm_finger_a_joint" multiplier="-1"/>
  </joint>
  <link name="arm_fork_tcp"/>
  <joint name="arm_fork-arm_fork_tcp" type="fixed">
    <origin rpy="0 0 0" xyz="0 -0.1613 -0.21765"/>
    <parent link="arm_finger_a"/>
    <child link="arm_fork_tcp"/>
  </joint>
  <link name="arm_d405">
    <collision>
      <origin rpy="0 0 0" xyz="0 0 0"/>
      <geometry>
        <mesh filename="package://roboplan_example_models/models/reachback_robot_model/meshes/d405.stl"/>
      </geometry>
    </collision>
    <visual>
      <origin rpy="0 0 0" xyz="0 0 0"/>
      <geometry>
        <mesh filename="package://roboplan_example_models/models/reachback_robot_model/meshes/d405.stl"/>
      </geometry>
      <material name="grey">
        <color rgba="0.2 0.2 0.2 1.0"/>
      </material>
    </visual>
  </link>
  <joint name="arm_eoat_adapter-arm_d405" type="fixed">
    <origin rpy="-2.838 -0.666 -0.895" xyz="0.05 0.04 -0.06"/>
    <parent link="arm_eoat_adapter"/>
    <child link="arm_d405"/>
  </joint>
  <link name="arm_gripper_tcp"/>
  <joint name="arm_gripper-arm_gripper_tcp" type="fixed">
    <origin rpy="0 0 0" xyz="0 -0.156 0.0"/>
    <parent link="arm_gripper"/>
    <child link="arm_gripper_tcp"/>
  </joint>
  <!-- Top assembly of ridgeback -->
  <link name="top_assembly_link">
    <visual>
      <origin rpy="0.0 0.0 0.0" xyz="0.0 0.0 0.0"/>
      <geometry>
        <mesh filename="package://roboplan_example_models/models/reachback_robot_model/meshes/ridgeback_top_assembly.stl"/>
      </geometry>
      <material name="blackish">
        <color rgba="0.15 0.15 0.15 1.0"/>
      </material>
    </visual>
    <collision>
      <origin rpy="0.0 0.0 0.0" xyz="0.0 0.0 0.0"/>
      <geometry>
        <mesh filename="package://roboplan_example_models/models/reachback_robot_model/meshes/ridgeback_top_assembly.stl"/>
      </geometry>
    </collision>
  </link>
  <joint name="default_mount-top_assembly_link" type="fixed">
    <origin rpy="0 0 0" xyz="0 0 0"/>
    <parent link="default_mount"/>
    <child link="top_assembly_link"/>
  </joint>
  <!-- Mount the arm to the mobile base -->
  <joint name="top_assembly_link-arm_base_link" type="fixed">
    <origin rpy="0 0 0" xyz="0.2 -0.04 0.056"/>
    <parent link="top_assembly_link"/>
    <child link="arm_base_link"/>
  </joint>
</robot>
